<!--
s-model_finder_articulated_macro(prefix)

Creates an articulated s-model finder with the passed in prefix.  The
prefix typcially includes the hand prefix and an identifier for the
finger(i.e. finger_1, etc...).

-->
<robot xmlns:xacro="http://ros.org/wiki/xacro">
	<xacro:macro name="s-model_finger_articulated" params="prefix">
		<!-- link list -->
		<link name="${prefix}link_0">
			<visual>
				<origin xyz="0.020 0 0" rpy="0 0 0"/>
				<geometry>
					<mesh filename="package://robotiq_s_model_visualization/meshes/s-model_articulated/visual/link_0.STL" />
				</geometry>
			</visual>
                        <!-- This collision link is broken and not proper, it prevents the whole gripper from being used in MoveIt! -->
			<!-- <collision>	
				<origin xyz="-0.0455 0.0414 0.036" rpy="0 3.1416 -1.57"/>
				<geometry>
					<mesh filename="package://robotiq_s_model_visualization/meshes/s-model_articulated/collision/link_0.STL" />
				</geometry>
			</collision> -->
            <inertial>
                <origin xyz="0 0 0" rpy="0 0 0"/>
                <mass value="0.05"/>
                <inertia ixx="0.01" ixy="-0.00002" ixz="0.00001" iyy="0.0008" iyz="0" izz="0.001" />
            </inertial>         
		</link>
                <gazebo reference="${prefix}link_0">
                    <material>Gazebo/Black</material>
                    <selfCollide>false</selfCollide>
                </gazebo>

		<link name="${prefix}link_1">
			<visual>
				<origin xyz="0.050 -.028 0" rpy="0 0 -0.52"/>
				<geometry>
					<mesh filename="package://robotiq_s_model_visualization/meshes/s-model_articulated/visual/link_1.STL" />
				</geometry>
			</visual>
			<collision>
				<origin xyz="0.050 -.028 0" rpy="0 0 -0.52"/>
				<geometry>
					<mesh filename="package://robotiq_s_model_visualization/meshes/s-model_articulated/collision/link_1.STL" />
				</geometry>
			</collision>
            <inertial>
                <origin xyz="0 0 0" rpy="0 0 0"/>
                <mass value="0.15"/>
                <inertia ixx="0.001859" ixy="-0.000376" ixz="0.000028" iyy="0.012756" iyz="0" izz="0.0024" />
            </inertial>
		</link>
                 <gazebo reference="${prefix}link_1">
                            <material>Gazebo/Black</material>
                            <selfCollide>false</selfCollide>
                 </gazebo>
		<link name="${prefix}link_2">
			<!--
			NOTE: This link has an offset in the z-direction based on the models that were
			used to generate grap-it poses.  With the offset below the model appears visually
			correct, but it is suspect.
			-->
			<visual>
				<origin xyz="0.039 0 0.0075" rpy="0 0 0"/>
				<geometry>
					<mesh filename="package://robotiq_s_model_visualization/meshes/s-model_articulated/visual/link_2.STL" />
				</geometry>
			</visual>
			<collision>
				<origin xyz="0.039 0 0.0075" rpy="0 0 0"/>
				<geometry>
					<mesh filename="package://robotiq_s_model_visualization/meshes/s-model_articulated/collision/link_2.STL" />
				</geometry>
			</collision>
            <inertial>
                <origin xyz="0 0 0" rpy="0 0 0"/>
                <mass value="0.15"/>
                <inertia ixx="0.001859" ixy="-0.000376" ixz="0.000028" iyy="0.012756" iyz="0" izz="0.0024" />
            </inertial>
		</link>
 <gazebo reference="${prefix}link_2">
				<material>Gazebo/Black</material>
                                <selfCollide>false</selfCollide>
                                </gazebo>
		<link name="${prefix}link_3">
			<visual>
				<origin xyz="0 0 0" rpy="0 0 0.52"/>
				<geometry>
					<mesh filename="package://robotiq_s_model_visualization/meshes/s-model_articulated/visual/link_3.STL" />
				</geometry>
			</visual>
			<collision>
				<origin xyz="0 0 0" rpy="0 0 0.52"/>
				<geometry>
					<mesh filename="package://robotiq_s_model_visualization/meshes/s-model_articulated/collision/link_3.STL" />
				</geometry>
			</collision>
            <inertial>
                <origin xyz="0 0 0" rpy="0 0 0"/>
                <mass value="0.05"/>
                <inertia ixx="0.001239" ixy="-0.000251" ixz="0.000019" iyy="0.00085" iyz="0" izz="0.001632" />
            </inertial>
		</link>
<gazebo reference="${prefix}link_2">
				<material>Gazebo/Black</material>
                                <selfCollide>false</selfCollide>
                                </gazebo>
		<!-- end of link list -->
		<!-- joint list -->
		
		<!-- WARNING: LIMITS NOT CORRECT -->
		<joint name="${prefix}joint_1" type="revolute">
			<parent link="${prefix}link_0"/>
			<child link="${prefix}link_1"/>
			<axis xyz="0 0 1"/>
			<origin xyz="0.020 0 0" rpy="0 0 0"/>
			<limit lower="0" upper="3.1416" effort="100" velocity="100"/>
		</joint>
		<!-- WARNING: LIMITS NOT CORRECT -->
		<joint name="${prefix}joint_2" type="revolute">
			<parent link="${prefix}link_1"/>
			<child link="${prefix}link_2"/>
			<axis xyz="0 0 1"/>
			<origin xyz="0.050 -.028 0" rpy="0 0 -0.52"/>
			<limit lower="0" upper="3.1416" effort="100" velocity="100"/>
		</joint>
		<!-- WARNING: LIMITS NOT CORRECT -->
		<joint name="${prefix}joint_3" type="revolute">
			<parent link="${prefix}link_2"/>
			<child link="${prefix}link_3"/>
			<axis xyz="0 0 1"/>
			<origin xyz="0.039 0 0" rpy="0 0 0"/>
			<limit lower="0" upper="3.1416" effort="100" velocity="100"/>
		</joint>
		<!-- end of joint list -->
	</xacro:macro>
</robot>
